Workbook

Sheet Codebook
A1: Codebook
A2: Variable name | B2: Variable Description
A3: SOURCE_AUTHOR | B3: First author of input source
A4: SOURCE_YEAR | B4: Year of publication
A5: SOURCE_TITLE | B5: Title of source
A6: SOURCE_URL | B6: URL of source, other than DOI (if available)
A7: OPT_ACCESS_DATE | B7: Date the reviewer accessed the source, for websites & grey literature
A8: OPT_STUDY_TYPE | B8: Study type of the input source
A9: OPT_OTHER_STUDY_TYPE | B9: Details if OPT_STUDY_TYPE = "Other"
A10: REF_YEAR_START | B10: Starting year of the data derived from the input source
A11: REF_YEAR_END | B11: End year of the data derived from the input source
A12: REF_LOC_LEVEL | B12: Location level investigated by the input source
A13: REF_LOCATION | B13: Geographic location for which the input source was used
... A28: VALUE_P97_5 | B28: 97.5th percentile of the data derived from the input source (upper limit 95%CI)

Sheet Incidence
A1: SOURCE_AUTHOR | B1: SOURCE_YEAR | C1: SOURCE_TITLE | D1: SOURCE_URL | E1: OPT_ACCESS_DATE | F1: OPT_STUDY_TYPE | G1: OPT_OTHER_STUDY_TYPE | H1: REF_YEAR_START | I1: REF_YEAR_END | J1: REF_LOCATION | K1: REF_LOCATION_ISO3 | L1: OPT_DISEASE | M1: REF_SAMPLE_SIZE | N1: VALUE_X | O1: VALUE_MEAN | P1: VALUE_MEDIAN | Q1: VALUE_DENOM | R1: VALUE_P2_5 | S1: VALUE_P5 | T1: VALUE_P10 | U1: VALUE_P25 | V1: VALUE_P75 | W1: VALUE_P90 | X1: VALUE_P95 | Y1: VALUE_P97_5
A2: Beninca | B2: 2024 | C2: Disease burden of foodrelated pathogens in the Netherlands, 2023 | D2: chrome-extension://efaidnbmnnnibpcajpcglclefindmkaj/https://www.rivm.nl/bibliotheek/rapporten/2024-0146.pdf | E2: 45748 | F2: Other | G2: National Burden study | H2: 2023 | I2: 2023 | J2: Netherlands | K2: =IF(J2<>"", VLOOKUP(J2, 'Drop down values'!$C$2:$D$195, 2, FALSE), "") -> NLD | L2: Campylobacter | O2: 56000 | R2: 9000 | Y2: 170000
A3: Beninca | B3: 2024 | C3: Disease burden of foodrelated pathogens in the Netherlands, 2023 | D3: chrome-extension://efaidnbmnnnibpcajpcglclefindmkaj/https://www.rivm.nl/bibliotheek/rapporten/2024-0146.pdf | E3: 45748 | F3: Other | G3: National Burden study | H3: 2023 | I3: 2023 | J3: Netherlands | K3: =IF(J3<>"", VLOOKUP(J3, 'Drop down values'!$C$2:$D$195, 2, FALSE), "") -> NLD | L3: Cryptosporidium | O3: 130000 | R3: 42000 | Y3: 340000
A4: Beninca | B4: 2024 | C4: Disease burden of foodrelated pathogens in the Netherlands, 2023 | D4: chrome-extension://efaidnbmnnnibpcajpcglclefindmkaj/https://www.rivm.nl/bibliotheek/rapporten/2024-0146.pdf | E4: 45748 | F4: Other | G4: National Burden study | H4: 2023 | I4: 2023 | J4: Netherlands | K4: =IF(J4<>"", VLOOKUP(J4, 'Drop down values'!$C$2:$D$195, 2, FALSE), "") -> NLD | L4: Giardia | O4: 83000 | R4: 41000 | Y4: 160000
A5: Beninca | B5: 2024 | C5: Disease burden of foodrelated pathogens in the Netherlands, 2023 | D5: chrome-extension://efaidnbmnnnibpcajpcglclefindmkaj/https://www.rivm.nl/bibliotheek/rapporten/2024-0146.pdf | E5: 45748 | F5: Other | G5: National Burden study | H5: 2023 | I5: 2023 | J5: Netherlands | K5: =IF(J5<>"", VLOOKUP(J5, 'Drop down values'!$C$2:$D$195, 2, FALSE), "") -> NLD | L5: Norovirus | O5: 740000 | R5: 500000 | Y5: 1100000
A6: Beninca | B6: 2024 | C6: Disease burden of foodrelated pathogens in the Netherlands, 2023 | D6: chrome-extension://efaidnbmnnnibpcajpcglclefindmkaj/https://www.rivm.nl/bibliotheek/rapporten/2024-0146.pdf | E6: 45748 | F6: Other | G6: National Burden study | H6: 2023 | I6: 2023 | J6: Netherlands | K6: =IF(J6<>"", VLOOKUP(J6, 'Drop down values'!$C$2:$D$195, 2, FALSE), "") -> NLD | L6: Rotavirus | O6: 190000 | R6: 93000 | Y6: 340000
A7: Beninca | B7: 2024 | C7: Disease burden of foodrelated pathogens in the Netherlands, 2023 | D7: chrome-extension://efaidnbmnnnibpcajpcglclefindmkaj/https://www.rivm.nl/bibliotheek/rapporten/2024-0146.pdf | E7: 45748 | F7: Other | G7: National Burden study | H7: 2023 | I7: 2023 | J7: Netherlands | K7: =IF(J7<>"", VLOOKUP(J7, 'Drop down values'!$C$2:$D$195, 2, FALSE), "") -> NLD | L7: Salmonella | O7: 41000 | R7: 4000 | Y7: 140000
A8: Cressey | B8: 2014 | C8: Risk Ranking: Updated Estimates of The Burden Of Foodborne Disease For New Zealand In 2013 | D8: https://www.mpi.govt.nz/dmsdocument/14146-Risk-Ranking-Updated-estimates-of-the-burden-of-foodborne-disease-for-New-Zealand-in-2013 | E8: 45716 | F8: Other | G8: National Burden study | H8: 2013 | I8: 2013 | J8: New Zealand | K8: =IF(J8<>"", VLOOKUP(J8, 'Drop down values'!$C$2:$D$195, 2, FALSE), "") -> NZL | L8: Campylobacter | O8: 65200 | S8: 44000 | X8: 92800
A9: Cressey | B9: 2011 | C9: Estimated incidence of foodborne illness in New Zealand: Application of overseas models and multipliers | D9: https://www.mpi.govt.nz/dmsdocument/4039-Estimated-incidence-of-foodborne-illness-in-New-Zealand-Application-of-overseas-models-and-multipliers | E9: 45716 | F9: Other | G9: National Burden study | H9: 2009 | I9: 2009 | J9: New Zealand | K9: =IF(J9<>"", VLOOKUP(J9, 'Drop down values'!$C$2:$D$195, 2, FALSE), "") -> NZL | L9: Campylobacter | O9: 68412 | S9: 46202 | X9: 96323
A10: Cressey | B10: 2014 | C10: Risk Ranking: Updated Estimates of The Burden Of Foodborne Disease For New Zealand In 2013 | D10: https://www.mpi.govt.nz/dmsdocument/14146-Risk-Ranking-Updated-estimates-of-the-burden-of-foodborne-disease-for-New-Zealand-in-2013 | E10: 45716 | F10: Other | G10: National Burden study | H10: 2011 | I10: 2011 | J10: New Zealand | K10: =IF(J10<>"", VLOOKUP(J10, 'Drop down values'!$C$2:$D$195, 2, FALSE), "") -> NZL | L10: Campylobacter | O10: 63800 | S10: 43000 | X10: 90000
A11: Cressey | B11: 2011 | C11: Estimated incidence of foodborne illness in New Zealand: Application of overseas models and multipliers | D11: https://www.mpi.govt.nz/dmsdocument/4039-Estimated-incidence-of-foodborne-illness-in-New-Zealand-Application-of-overseas-models-and-multipliers | E11: 45716 | F11: Other | G11: National Burden study | H11: 2009 | I11: 2009 | J11: New Zealand | K11: =IF(J11<>"", VLOOKUP(J11, 'Drop down values'!$C$2:$D$195, 2, FALSE), "") -> NZL | L11: Cryptosporidium | O11: 8882 | S11: 2235 | X11: 21787
A12: Cressey | B12: 2011 | C12: Estimated incidence of foodborne illness in New Zealand: Application of overseas models and multipliers | D12: https://www.mpi.govt.nz/dmsdocument/4039-Estimated-incidence-of-foodborne-illness-in-New-Zealand-Application-of-overseas-models-and-multipliers | E12: 45716 | F12: Other | G12: National Burden study | H12: 2009 | I12: 2009 | J12: New Zealand | K12: =IF(J12<>"", VLOOKUP(J12, 'Drop down values'!$C$2:$D$195, 2, FALSE), "") -> NZL | L12: Giardia intestinalis | O12: 28164 | S12: 8024 | X12: 65700
A13: Cressey | B13: 2014 | C13: Risk Ranking: Updated Estimates of The Burden Of Foodborne Disease For New Zealand In 2013 | D13: https://www.mpi.govt.nz/dmsdocument/14146-Risk-Ranking-Updated-estimates-of-the-burden-of-foodborne-disease-for-New-Zealand-in-2013 | E13: 45716 | F13: Other | G13: National Burden study | H13: 2013 | I13: 2013 | J13: New Zealand | K13: =IF(J13<>"", VLOOKUP(J13, 'Drop down values'!$C$2:$D$195, 2, FALSE), "") -> NZL | L13: Norovirus | O13: 211000 | S13: 180000 | X13: 245000
A14: Cressey | B14: 2014 | C14: Risk Ranking: Updated Estimates of The Burden Of Foodborne Disease For New Zealand In 2013 | D14: https://www.mpi.govt.nz/dmsdocument/14146-Risk-Ranking-Updated-estimates-of-the-burden-of-foodborne-disease-for-New-Zealand-in-2013 | E14: 45716 | F14: Other | G14: National Burden study | H14: 2011 | I14: 2011 | J14: New Zealand | K14: =IF(J14<>"", VLOOKUP(J14, 'Drop down values'!$C$2:$D$195, 2, FALSE), "") -> NZL | L14: Norovirus | O14: 208000 | S14: 178000 | X14: 242000
A15: Cressey | B15: 2011 | C15: Estimated incidence of foodborne illness in New Zealand: Application of overseas models and multipliers | D15: https://www.mpi.govt.nz/dmsdocument/4039-Estimated-incidence-of-foodborne-illness-in-New-Zealand-Application-of-overseas-models-and-multipliers | E15: 45716 | F15: Other | G15: National Burden study | H15: 2009 | I15: 2009 | J15: New Zealand | K15: =IF(J15<>"", VLOOKUP(J15, 'Drop down values'!$C$2:$D$195, 2, FALSE), "") -> NZL | L15: Salmonella spp., non-typhoidal | O15: 6734 | S15: 1690 | X15: 16533
A16: Cressey | B16: 2014 | C16: Risk Ranking: Updated Estimates of The Burden Of Foodborne Disease For New Zealand In 2013 | D16: https://www.mpi.govt.nz/dmsdocument/14146-Risk-Ranking-Updated-estimates-of-the-burden-of-foodborne-disease-for-New-Zealand-in-2013 | E16: 45716 | F16: Other | G16: National Burden study | H16: 2013 | I16: 2013 | J16: New Zealand | K16: =IF(J16<>"", VLOOKUP(J16, 'Drop down values'!$C$2:$D$195, 2, FALSE), "") -> NZL | L16: Salmonella spp., non-typhoidal | O16: 6820 | S16: 1710 | X16: 16700
A17: Cressey | B17: 2014 | C17: Risk Ranking: Updated Estimates of The Burden Of Foodborne Disease For New Zealand In 2013 | D17: https://www.mpi.govt.nz/dmsdocument/14146-Risk-Ranking-Updated-estimates-of-the-burden-of-foodborne-disease-for-New-Zealand-in-2013 | E17: 45716 | F17: Other | G17: National Burden study | H17: 2011 | I17: 2011 | J17: New Zealand | K17: =IF(J17<>"", VLOOKUP(J17, 'Drop down values'!$C$2:$D$195, 2, FALSE), "") -> NZL | L17: Salmonella spp., non-typhoidal | O17: 6300 | S17: 1600 | X17: 15500
A18: Cressey | B18: 2014 | C18: Risk Ranking: Updated Estimates of The Burden Of Foodborne Disease For New Zealand In 2013 | D18: https://www.mpi.govt.nz/dmsdocument/14146-Risk-Ranking-Updated-estimates-of-the-burden-of-foodborne-disease-for-New-Zealand-in-2013 | E18: 45716 | F18: Other | G18: National Burden study | H18: 2013 | I18: 2013 | J18: New Zealand | K18: =IF(J18<>"", VLOOKUP(J18, 'Drop down values'!$C$2:$D$195, 2, FALSE), "") -> NZL | L18: STEC | O18: 3800 | S18: 160 | X18: 14100
A19: Cressey | B19: 2014 | C19: Risk Ranking: Updated Estimates of The Burden Of Foodborne Disease For New Zealand In 2013 | D19: https://www.mpi.govt.nz/dmsdocument/14146-Risk-Ranking-Updated-estimates-of-the-burden-of-foodborne-disease-for-New-Zealand-in-2013 | E19: 45716 | F19: Other | G19: National Burden study | H19: 2011 | I19: 2011 | J19: New Zealand | K19: =IF(J19<>"", VLOOKUP(J19, 'Drop down values'!$C$2:$D$195, 2, FALSE), "") -> NZL | L19: STEC | O19: 2830 | S19: 120 | X19: 10500
A20: Ford | B20: 2019 | C20: Cost of Salmonella Infections in Australia, 2015 | D20: https://www.sciencedirect.com/science/article/pii/S0362028X22099057?via%3Dihub | E20: 45373 | F20: Other | G20: National Burden study | H20: 2015 | I20: 2015 | J20: Australia | K20: =IF(J20<>"", VLOOKUP(J20, 'Drop down values'!$C$2:$D$195, 2, FALSE), "") -> AUS | L20: Salmonella | N20: 90853 | S20: 51583 | X20: 158165
A21: Glass | B21: 2023 | C21: The Cost of Foodborne Illness and Its Sequelae in Australia Circa 2023 | D21: https://pubmed.ncbi.nlm.nih.gov/37610847/ | E21: 45425 | F21: Other | G21: National Burden study | H21: 2019 | I21: 2019 | J21: Australia | K21: =IF(J21<>"", VLOOKUP(J21, 'Drop down values'!$C$2:$D$195, 2, FALSE), "") -> AUS | L21: STEC | N21: 2630 | S21: 1140 | X21: 5760
A22: Glass | B22: 2023 | C22: The Cost of Foodborne Illness and Its Sequelae in Australia Circa 2019 | D22: https://pubmed.ncbi.nlm.nih.gov/37610847/ | E22: 45425 | F22: Other | G22: National Burden study | H22: 2019 | I22: 2019 | J22: Australia | K22: =IF(J22<>"", VLOOKUP(J22, 'Drop down values'!$C$2:$D$195, 2, FALSE), "") -> AUS | L22: Campylobacter | N22: 264000 | S22: 161000 | X22: 432000
A23: Glass | B23: 2023 | C23: The Cost of Foodborne Illness and Its Sequelae in Australia Circa 2024 | D23: https://pubmed.ncbi.nlm.nih.gov/37610847/ | E23: 45425 | F23: Other | G23: National Burden study | H23: 2019 | I23: 2019 | J23: Australia | K23: =IF(J23<>"", VLOOKUP(J23, 'Drop down values'!$C$2:$D$195, 2, FALSE), "") -> AUS | L23: EPEC | N23: 312000 | S23: 120000 | X23: 709000
A24: Glass | B24: 2023 | C24: The Cost of Foodborne Illness and Its Sequelae in Australia Circa 2021 | D24: https://pubmed.ncbi.nlm.nih.gov/37610847/ | E24: 45425 | F24: Other | G24: National Burden study | H24: 2019 | I24: 2019 | J24: Australia | K24: =IF(J24<>"", VLOOKUP(J24, 'Drop down values'!$C$2:$D$195, 2, FALSE), "") -> AUS | L24: Norovirus | N24: 328000 | S24: 89600 | X24: 671000
A25: Glass | B25: 2023 | C25: The Cost of Foodborne Illness and Its Sequelae in Australia Circa 2020 | D25: https://pubmed.ncbi.nlm.nih.gov/37610847/ | E25: 45425 | F25: Other | G25: National Burden study | H25: 2019 | I25: 2019 | J25: Australia | K25: =IF(J25<>"", VLOOKUP(J25, 'Drop down values'!$C$2:$D$195, 2, FALSE), "") -> AUS | L25: Salmonella | N25: 61600 | S25: 34300 | X25: 109000
A26: Glass | B26: 2023 | C26: The Cost of Foodborne Illness and Its Sequelae in Australia Circa 2025 | D26: https://pubmed.ncbi.nlm.nih.gov/37610847/ | E26: 45425 | F26: Other | G26: National Burden study | H26: 2019 | I26: 2019 | J26: Australia | K26: =IF(J26<>"", VLOOKUP(J26, 'Drop down values'!$C$2:$D$195, 2, FALSE), "") -> AUS | L26: Salmonella | N26: 29 | S26: 10 | X26: 34
A27: Glass | B27: 2023 | C27: The Cost of Foodborne Illness and Its Sequelae in Australia Circa 2022 | D27: https://pubmed.ncbi.nlm.nih.gov/37610847/ | E27: 45425 | F27: Other | G27: National Burden study | H27: 2019 | I27: 2019 | J27: Australia | K27: =IF(J27<>"", VLOOKUP(J27, 'Drop down values'!$C$2:$D$195, 2, FALSE), "") -> AUS | L27: Shigella | N27: 1930 | S27: 662 | X27: 4360
A28: Glass-Kaastra | B28: 2022 | C28: Estimated Reduction in the Burden of Nontyphoidal Salmonella Illness in Canada Circa 2019. | D28: https://www.liebertpub.com/doi/10.1089/fpd.2022.0045 | E28: 45419 | F28: Other | G28: National Burden study | H28: 2019 | I28: 2019 | J28: Canada | K28: =IF(J28<>"", VLOOKUP(J28, 'Drop down values'!$C$2:$D$195, 2, FALSE), "") -> CAN | L28: Salmonella | O28: 70833 | S28: 49594 | X28: 98667
A29: Grytdal | B29: 2016 | C29: Incidence of Norovirus and Other Viral Pathogens That Cause Acute Gastroenteritis (AGE) among Kaiser Permanente Member Populations in the United States, 2012–2013 | D29: https://www.ncbi.nlm.nih.gov/pmc/articles/PMC4846013/ | E29: 45374 | F29: Other | G29: National Burden study | H29: 2012 | I29: 2013 | J29: United States of America | K29: =IF(J29<>"", VLOOKUP(J29, 'Drop down values'!$C$2:$D$195, 2, FALSE), "") -> USA | L29: Norovirus | N29: 68.9 | Q29: 1000 | R29: 57.7 | Y29: 77.1
A30: Grytdal | B30: 2016 | C30: Incidence of Norovirus and Other Viral Pathogens That Cause Acute Gastroenteritis (AGE) among Kaiser Permanente Member Populations in the United States, 2012–2013 | D30: https://www.ncbi.nlm.nih.gov/pmc/articles/PMC4846013/ | E30: 45374 | F30: Other | G30: National Burden study | H30: 2012 | I30: 2013 | J30: United States of America | K30: =IF(J30<>"", VLOOKUP(J30, 'Drop down values'!$C$2:$D$195, 2, FALSE), "") -> USA | L30: Rotavirus | N30: 23.7 | Q30: 1000 | R30: 20.2 | Y30: 26.9
A31: Haagsma | B31: 2013 | C31: Community incidence of pathogen-specific gastroenteritis: reconstructing the surveillance pyramid for seven pathogens in seven European Union member states | D31: https://www.ncbi.nlm.nih.gov/pmc/articles/PMC9151593/ | E31: 45374 | F31: Other | G31: National Burden study | H31: 2001 | I31: 2009 | J31: Germany | K31: =IF(J31<>"", VLOOKUP(J31, 'Drop down values'!$C$2:$D$195, 2, FALSE), "") -> DEU | L31: Campylobacter | P31: 515000
A32: Haagsma | B32: 2013 | C32: Community incidence of pathogen-specific gastroenteritis: reconstructing the surveillance pyramid for seven pathogens in seven European Union member states | D32: https://www.ncbi.nlm.nih.gov/pmc/articles/PMC9151593/ | E32: 45374 | F32: Other | G32: National Burden study | H32: 2001 | I32: 2009 | J32: Germany | K32: =IF(J32<>"", VLOOKUP(J32, 'Drop down values'!$C$2:$D$195, 2, FALSE), "") -> DEU | L32: Cryptosporidium | P32: 109000
A33: Haagsma | B33: 2013 | C33: Community incidence of pathogen-specific gastroenteritis: reconstructing the surveillance pyramid for seven pathogens in seven European Union member states | D33: https://www.ncbi.nlm.nih.gov/pmc/articles/PMC9151593/ | E33: 45374 | F33: Other | G33: National Burden study | H33: 2001 | I33: 2009 | J33: Germany | K33: =IF(J33<>"", VLOOKUP(J33, 'Drop down values'!$C$2:$D$195, 2, FALSE), "") -> DEU | L33: EPEC | P33: 117000
A34: Haagsma | B34: 2013 | C34: Community incidence of pathogen-specific gastroenteritis: reconstructing the surveillance pyramid for seven pathogens in seven European Union member states | D34: https://www.ncbi.nlm.nih.gov/pmc/articles/PMC9151593/ | E34: 45374 | F34: Other | G34: National Burden study | H34: 2001 | I34: 2009 | J34: Germany | K34: =IF(J34<>"", VLOOKUP(J34, 'Drop down values'!$C$2:$D$195, 2, FALSE), "") -> DEU | L34: Salmonella | P34: 430000
A35: Haagsma | B35: 2013 | C35: Community incidence of pathogen-specific gastroenteritis: reconstructing the surveillance pyramid for seven pathogens in seven European Union member states | D35: https://www.ncbi.nlm.nih.gov/pmc/articles/PMC9151593/ | E35: 45374 | F35: Other | G35: National Burden study | H35: 2001 | I35: 2009 | J35: Germany | K35: =IF(J35<>"", VLOOKUP(J35, 'Drop down values'!$C$2:$D$195, 2, FALSE), "") -> DEU | L35: Shigella | P35: 12000
A36: Haagsma | B36: 2013 | C36: Community incidence of pathogen-specific gastroenteritis: reconstructing the surveillance pyramid for seven pathogens in seven European Union member states | D36: https://www.ncbi.nlm.nih.gov/pmc/articles/PMC9151593/ | E36: 45374 | F36: Other | G36: National Burden study | H36: 2001 | I36: 2009 | J36: Denmark | K36: =IF(J36<>"", VLOOKUP(J36, 'Drop down values'!$C$2:$D$195, 2, FALSE), "") -> DNK | L36: Campylobacter | P36: 116000
A37: Haagsma | B37: 2013 | C37: Community incidence of pathogen-specific gastroenteritis: reconstructing the surveillance pyramid for seven pathogens in seven European Union member states | D37: https://www.ncbi.nlm.nih.gov/pmc/articles/PMC9151593/ | E37: 45374 | F37: Other | G37: National Burden study | H37: 2001 | I37: 2009 | J37: Denmark | K37: =IF(J37<>"", VLOOKUP(J37, 'Drop down values'!$C$2:$D$195, 2, FALSE), "") -> DNK | L37: EPEC | P37: 47000
A38: Haagsma | B38: 2013 | C38: Community incidence of pathogen-specific gastroenteritis: reconstructing the surveillance pyramid for seven pathogens in seven European Union member states | D38: https://www.ncbi.nlm.nih.gov/pmc/articles/PMC9151593/ | E38: 45374 | F38: Other | G38: National Burden study | H38: 2001 | I38: 2009 | J38: Denmark | K38: =IF(J38<>"", VLOOKUP(J38, 'Drop down values'!$C$2:$D$195, 2, FALSE), "") -> DNK | L38: Salmonella | P38: 33000
A39: Haagsma | B39: 2013 | C39: Community incidence of pathogen-specific gastroenteritis: reconstructing the surveillance pyramid for seven pathogens in seven European Union member states | D39: https://www.ncbi.nlm.nih.gov/pmc/articles/PMC9151593/ | E39: 45374 | F39: Other | G39: National Burden study | H39: 2001 | I39: 2009 | J39: Denmark | K39: =IF(J39<>"", VLOOKUP(J39, 'Drop down values'!$C$2:$D$195, 2, FALSE), "") -> DNK | L39: Shigella | P39: 4400
A40: Haagsma | B40: 2013 | C40: Community incidence of pathogen-specific gastroenteritis: reconstructing the surveillance pyramid for seven pathogens in seven European Union member states | D40: https://www.ncbi.nlm.nih.gov/pmc/articles/PMC9151593/ | E40: 45374 | F40: Other | G40: National Burden study | H40: 2001 | I40: 2009 | J40: United Kingdom | K40: =IF(J40<>"", VLOOKUP(J40, 'Drop down values'!$C$2:$D$195, 2, FALSE), "") -> GBR | L40: Campylobacter | P40: 2500000
...

Sheet Mortality
A1: SOURCE_AUTHOR | B1: SOURCE_YEAR | C1: SOURCE_TITLE | D1: SOURCE_URL | E1: OPT_ACCESS_DATE | F1: OPT_STUDY_TYPE | G1: OPT_OTHER_STUDY_TYPE | H1: REF_YEAR_START | I1: REF_YEAR_END | J1: REF_LOCATION | K1: REF_LOCATION_ISO3 | L1: REF_SEX | M1: REF_AGE_START | N1: REF_AGE_END | O1: OPT_MEAN_AGE | P1: OPT_MEDIAN_AGE | Q1: OPT_SUBPOP | R1: OPT_CASES | S1: OPT_DISEASE | T1: REF_SAMPLE_SIZE | U1: VALUE_X | V1: VALUE_MEAN | W1: VALUE_MEDIAN | X1: VALUE_DENOM | Y1: VALUE_SE | Z1: VALUE_P000 | AA1: VALUE_P2_5 | AB1: VALUE_P5 | AC1: VALUE_P10 | AD1: VALUE_P25 | AE1: VALUE_P75 | AF1: VALUE_P90 | AG1: VALUE_P95 | AH1: VALUE_P97_5
A2: Beninca | B2: 2024 | C2: Disease burden of foodrelated pathogens in the Netherlands, 2023 | D2: chrome-extension://efaidnbmnnnibpcajpcglclefindmkaj/https://www.rivm.nl/bibliotheek/rapporten/2024-0146.pdf | E2: 45748 | F2: Other | G2: National Burden study | H2: 2023 | I2: 2023 | J2: Netherlands | K2: =IF(J2<>"", VLOOKUP(J2, 'Drop down values'!$C$2:$D$195, 2, FALSE), "") -> NLD | S2: Campylobacter | V2: 37 | AA2: 25 | AH2: 52
A3: Cressey | B3: 2011 | C3: Estimated incidence of foodborne illness in New Zealand: Application of overseas models and multipliers | D3: https://www.mpi.govt.nz/dmsdocument/4039-Estimated-incidence-of-foodborne-illness-in-New-Zealand-Application-of-overseas-models-and-multipliers | E3: 45716 | F3: Other | G3: National Burden study | H3: 2009 | I3: 2009 | J3: New Zealand | K3: =IF(J3<>"", VLOOKUP(J3, 'Drop down values'!$C$2:$D$195, 2, FALSE), "") -> NZL | S3: Campylobacter | V3: 0 | AB3: 0 | AH3: 0
A4: Glass | B4: 2023 | C4: The Cost of Foodborne Illness and Its Sequelae in Australia Circa 2019 | D4: https://pubmed.ncbi.nlm.nih.gov/37610847/ | E4: 45425 | F4: Other | G4: National Burden study | H4: 2019 | I4: 2019 | J4: Australia | K4: =IF(J4<>"", VLOOKUP(J4, 'Drop down values'!$C$2:$D$195, 2, FALSE), "") -> AUS | S4: Campylobacter | U4: 4 | AB4: 2 | AG4: 5
A5: Havelaar | B5: 2012 | C5: Disease burden of foodborne pathogens in the Netherlands, 2009 | D5: https://pubmed.ncbi.nlm.nih.gov/22541392/ | E5: 45383 | F5: Other | G5: National Burden study | H5: 2009 | I5: 2009 | J5: Netherlands | K5: =IF(J5<>"", VLOOKUP(J5, 'Drop down values'!$C$2:$D$195, 2, FALSE), "") -> NLD | S5: Campylobacter | U5: 38 | AA5: 25 | AG5: 53
A6: Holland | B6: 2020 | C6: Estimating deaths from foodborne disease in the UK for 11 key pathogens | D6: https://bmjopengastro.bmj.com/content/7/1/e000377 | E6: 45419 | F6: Other | G6: National Burden study | H6: 2018 | I6: 2018 | J6: United Kingdom | K6: =IF(J6<>"", VLOOKUP(J6, 'Drop down values'!$C$2:$D$195, 2, FALSE), "") -> GBR | S6: Campylobacter | U6: 45 | AA6: 24 | AH6: 84
A7: Lake | B7: 2000 | C7: Estimated number of cases of foodborne infectious disease in New Zealand | D7: https://pubmed.ncbi.nlm.nih.gov/10935567/ | E7: 45407 | F7: Other | G7: National Burden study | H7: 2000 | I7: 2000 | J7: New Zealand | K7: =IF(J7<>"", VLOOKUP(J7, 'Drop down values'!$C$2:$D$195, 2, FALSE), "") -> NZL | S7: Campylobacter | U7: 1.7
A8: Mangen | B8: 2017 | C8: Disease burden of food-related pathogens in the Netherlands, 2016 | D8: chrome-extension://efaidnbmnnnibpcajpcglclefindmkaj/https://www.rivm.nl/bibliotheek/rapporten/2017-0097.pdf | E8: 45748 | F8: Other | G8: National Burden study | H8: 2016 | I8: 2016 | J8: Netherlands | K8: =IF(J8<>"", VLOOKUP(J8, 'Drop down values'!$C$2:$D$195, 2, FALSE), "") -> NLD | S8: Campylobacter | V8: 57 | AA8: 38 | AH8: 79
A9: Mead | B9: 1999 | C9: Food-related illness and death in the United States. | D9: https://www.ncbi.nlm.nih.gov/pmc/articles/PMC2627714/ | E9: 45390 | F9: Other | G9: National Burden study | H9: 1997 | I9: 1997 | J9: United States of America | K9: =IF(J9<>"", VLOOKUP(J9, 'Drop down values'!$C$2:$D$195, 2, FALSE), "") -> USA | S9: Campylobacter | U9: 124
A10: Pires | B10: 2020 | C10: Burden of Disease Estimates of Seven Pathogens Commonly Transmitted Through Foods in Denmark, 2017 | D10: https://orbit.dtu.dk/en/publications/burden-of-disease-estimates-of-seven-pathogens-commonly-transmitt | E10: 45390 | F10: Other | G10: National Burden study | H10: 2017 | I10: 2017 | J10: Denmark | K10: =IF(J10<>"", VLOOKUP(J10, 'Drop down values'!$C$2:$D$195, 2, FALSE), "") -> DNK | S10: Campylobacter | U10: 56
A11: Pires | B11: 2022 | C11: Health and Economic Burden of Seven Foodborne Diseases in Denmark, 2019 | D11: https://www.liebertpub.com/doi/10.1089/fpd.2022.0031 | E11: 45419 | F11: Other | G11: National Burden study | H11: 2019 | I11: 2019 | J11: Denmark | K11: =IF(J11<>"", VLOOKUP(J11, 'Drop down values'!$C$2:$D$195, 2, FALSE), "") -> DNK | S11: Campylobacter | U11: 41
A12: Scallan | B12: 2011 | C12: Foodborne illness acquired in the United States--major pathogens United States—Major Pathogens | D12: https://www.ncbi.nlm.nih.gov/pmc/articles/PMC3375761/ | E12: 45352 | F12: Other | G12: National Burden study | H12: 2006 | I12: 2006 | J12: United States of America | K12: =IF(J12<>"", VLOOKUP(J12, 'Drop down values'!$C$2:$D$195, 2, FALSE), "") -> USA | S12: Campylobacter | U12: 119 | AB12: 0 | AG12: 523
A13: Scallan Walter | B13: 2025 | C13: Foodborne Illness Acquired in the United States—Major Pathogens, 2019 | D13: https://pmc.ncbi.nlm.nih.gov/articles/PMC11950263/ | E13: 45748 | F13: Other | G13: National Burden study | H13: 2019 | I13: 2019 | J13: United States of America | K13: =IF(J13<>"", VLOOKUP(J13, 'Drop down values'!$C$2:$D$195, 2, FALSE), "") -> USA | S13: Campylobacter | V13: 420 | AB13: 0 | AG13: 1178
A14: Sundström | B14: 2018 | C14: Cost of Illness for Five Major Foodborne Illnesses and Sequelae in Sweden | D14: https://www.ncbi.nlm.nih.gov/pmc/articles/PMC5874275/ | E14: 45392 | F14: Other | G14: National Burden study | H14: 2012 | I14: 2016 | J14: Sweden | K14: =IF(J14<>"", VLOOKUP(J14, 'Drop down values'!$C$2:$D$195, 2, FALSE), "") -> SWE | S14: Campylobacter | U14: 4 | AB14: 2 | AG14: 7
A15: VanCauteren | B15: 2017 | C15: Estimated Annual Numbers of Foodborne Pathogen–Associated Illnesses, Hospitalizations, and Deaths, France, 2008–2013 | D15: https://wwwnc.cdc.gov/eid/article/23/9/17-0081_article | E15: 45406 | F15: Other | G15: National Burden study | H15: 2010 | I15: 2010 | J15: France | K15: =IF(J15<>"", VLOOKUP(J15, 'Drop down values'!$C$2:$D$195, 2, FALSE), "") -> FRA | S15: Campylobacter | U15: 52 | AB15: 33 | AG15: 82
A16: Klopfenstein | B16: 2024 | C16: Burden of Disease of Campylobacteriosis | E16: 45897 | F16: Other | G16: National Burden study | H16: 2022 | I16: 2022 | J16: Switzerland | S16: Campylobacter | U16: 6.4
A17: Van Lier | B17: 2016 | C17: Disease Burden of 32 Infectious Diseases in the Netherlands, 2007-2011 | D17: https://journals.plos.org/plosone/article?id=10.1371/journal.pone.0153106 | E17: 45918 | F17: Other | G17: National Burden study | H17: 2007 | I17: 2011 | J17: Netherlands | K17: =IF(J17<>"", VLOOKUP(J17, 'Drop down values'!$C$2:$D$195, 2, FALSE), "") -> NLD | S17: Campylobacter | U17: 39
A18: Thomas | B18: 2015 | C18: Estimates of Foodborne Illness–Related Hospitalizations and Deaths in Canada for 30 Specified Pathogens and Unspecified Agents | D18: https://pubmed.ncbi.nlm.nih.gov/26259128/ | E18: 45994 | F18: Other | G18: National Burden study | H18: 2000 | I18: 2010 | J18: Canada | S18: Campylobacter | U18: 11 | AB18: 3 | AG18: 25
A19: Cressey | B19: 2014 | C19: Risk Ranking: Updated Estimates of The Burden Of Foodborne Disease For New Zealand In 2013 | D19: https://www.mpi.govt.nz/dmsdocument/14146-Risk-Ranking-Updated-estimates-of-the-burden-of-foodborne-disease-for-New-Zealand-in-2013 | E19: 45716 | F19: Other | G19: National Burden study | H19: 2013 | I19: 2013 | J19: New Zealand | K19: =IF(J19<>"", VLOOKUP(J19, 'Drop down values'!$C$2:$D$195, 2, FALSE), "") -> NZL | S19: Campylobacter | V19: 0.4 | AB19: 0 | AH19: 2
A20: Cressey | B20: 2014 | C20: Risk Ranking: Updated Estimates of The Burden Of Foodborne Disease For New Zealand In 2013 | D20: https://www.mpi.govt.nz/dmsdocument/14146-Risk-Ranking-Updated-estimates-of-the-burden-of-foodborne-disease-for-New-Zealand-in-2013 | E20: 45716 | F20: Other | G20: National Burden study | H20: 2011 | I20: 2011 | J20: New Zealand | K20: =IF(J20<>"", VLOOKUP(J20, 'Drop down values'!$C$2:$D$195, 2, FALSE), "") -> NZL | S20: Campylobacter | V20: 0.4 | AB20: 0 | AH20: 2
A21: Kirk | B21: 2014 | C21: Foodborne illness, Australia, circa 2000 and circa 2010 | D21: https://www.ncbi.nlm.nih.gov/pmc/articles/PMC4214288/ | E21: 45383 | F21: Other | G21: National Burden study | H21: 2010 | I21: 2010 | J21: Australia | K21: =IF(J21<>"", VLOOKUP(J21, 'Drop down values'!$C$2:$D$195, 2, FALSE), "") -> AUS | S21: Campylobacter | U21: 4 | AB21: 3 | AG21: 5
A22: Mead | B22: 1999 | C22: Food-related illness and death in the United States. | D22: https://www.ncbi.nlm.nih.gov/pmc/articles/PMC2627714/ | E22: 45390 | F22: Other | G22: National Burden study | H22: 1997 | I22: 1997 | J22: United States of America | K22: =IF(J22<>"", VLOOKUP(J22, 'Drop down values'!$C$2:$D$195, 2, FALSE), "") -> USA | S22: Crypstosporidium | U22: 66
A23: Beninca | B23: 2024 | C23: Disease burden of foodrelated pathogens in the Netherlands, 2023 | D23: chrome-extension://efaidnbmnnnibpcajpcglclefindmkaj/https://www.rivm.nl/bibliotheek/rapporten/2024-0146.pdf | E23: 45748 | F23: Other | G23: National Burden study | H23: 2023 | I23: 2023 | J23: Netherlands | K23: =IF(J23<>"", VLOOKUP(J23, 'Drop down values'!$C$2:$D$195, 2, FALSE), "") -> NLD | S23: Cryptosporidium | V23: 8 | AA23: 0.16 | AH23: 36
A24: Cressey | B24: 2011 | C24: Estimated incidence of foodborne illness in New Zealand: Application of overseas models and multipliers | D24: https://www.mpi.govt.nz/dmsdocument/4039-Estimated-incidence-of-foodborne-illness-in-New-Zealand-Application-of-overseas-models-and-multipliers | E24: 45716 | F24: Other | G24: National Burden study | H24: 2009 | I24: 2009 | J24: New Zealand | K24: =IF(J24<>"", VLOOKUP(J24, 'Drop down values'!$C$2:$D$195, 2, FALSE), "") -> NZL | S24: Cryptosporidium | V24: 0 | AB24: 0 | AH24: 0
A25: Havelaar | B25: 2012 | C25: Disease burden of foodborne pathogens in the Netherlands, 2010 | D25: https://pubmed.ncbi.nlm.nih.gov/22541392/ | E25: 45383 | F25: Other | G25: National Burden study | H25: 2009 | I25: 2009 | J25: Netherlands | K25: =IF(J25<>"", VLOOKUP(J25, 'Drop down values'!$C$2:$D$195, 2, FALSE), "") -> NLD | S25: Cryptosporidium | U25: 1.7 | AA25: 0 | AG25: 8
A26: Holland | B26: 2020 | C26: Estimating deaths from foodborne disease in the UK for 11 key pathogens | D26: https://bmjopengastro.bmj.com/content/7/1/e000377 | E26: 45419 | F26: Other | G26: National Burden study | H26: 2018 | I26: 2018 | J26: United Kingdom | K26: =IF(J26<>"", VLOOKUP(J26, 'Drop down values'!$C$2:$D$195, 2, FALSE), "") -> GBR | S26: Cryptosporidium | U26: 8 | AA26: 1 | AH26: 43
A27: Mangen | B27: 2017 | C27: Disease burden of food-related pathogens in the Netherlands, 2016 | D27: chrome-extension://efaidnbmnnnibpcajpcglclefindmkaj/https://www.rivm.nl/bibliotheek/rapporten/2017-0097.pdf | E27: 45748 | F27: Other | G27: National Burden study | H27: 2016 | I27: 2016 | J27: Netherlands | K27: =IF(J27<>"", VLOOKUP(J27, 'Drop down values'!$C$2:$D$195, 2, FALSE), "") -> NLD | S27: Cryptosporidium | V27: 7 | AA27: 0 | AH27: 30
A28: Scallan | B28: 2011 | C28: Foodborne illness acquired in the United States--major pathogens United States—Major Pathogens | D28: https://www.ncbi.nlm.nih.gov/pmc/articles/PMC3375761/ | E28: 45352 | F28: Other | G28: National Burden study | H28: 2006 | I28: 2006 | J28: United States of America | K28: =IF(J28<>"", VLOOKUP(J28, 'Drop down values'!$C$2:$D$195, 2, FALSE), "") -> USA | S28: Cryptosporidium | U28: 46 | AB28: 0 | AG28: 241
A29: Van Lier | B29: 2016 | C29: Disease Burden of 32 Infectious Diseases in the Netherlands, 2007-2011 | D29: https://journals.plos.org/plosone/article?id=10.1371/journal.pone.0153106 | E29: 45918 | F29: Other | G29: National Burden study | H29: 2007 | I29: 2011 | J29: Netherlands | K29: =IF(J29<>"", VLOOKUP(J29, 'Drop down values'!$C$2:$D$195, 2, FALSE), "") -> NLD | S29: Cryptosporidium | U29: 2
A30: Thomas | B30: 2015 | C30: Estimates of Foodborne Illness–Related Hospitalizations and Deaths in Canada for 30 Specified Pathogens and Unspecified Agents | D30: https://pubmed.ncbi.nlm.nih.gov/26259128/ | E30: 45995 | F30: Other | G30: National Burden study | H30: 2000 | I30: 2010 | J30: Canada | S30: Cryptosporidium | U30: 1 | AB30: 0 | AG30: 4
A31: Kirk | B31: 2014 | C31: Foodborne illness, Australia, circa 2000 and circa 2018 | D31: https://www.ncbi.nlm.nih.gov/pmc/articles/PMC4214288/ | E31: 45383 | F31: Other | G31: National Burden study | H31: 2010 | I31: 2010 | J31: Australia | K31: =IF(J31<>"", VLOOKUP(J31, 'Drop down values'!$C$2:$D$195, 2, FALSE), "") -> AUS | S31: Cryptosporidium, foodborne | U31: 0 | AB31: 0 | AG31: 0
A32: Mead | B32: 1999 | C32: Food-related illness and death in the United States. | D32: https://www.ncbi.nlm.nih.gov/pmc/articles/PMC2627714/ | E32: 45390 | F32: Other | G32: National Burden study | H32: 1997 | I32: 1997 | J32: United States of America | K32: =IF(J32<>"", VLOOKUP(J32, 'Drop down values'!$C$2:$D$195, 2, FALSE), "") -> USA | S32: Cyclospora | U32: 0
A33: Scallan | B33: 2011 | C33: Foodborne illness acquired in the United States--major pathogens United States—Major Pathogens | D33: https://www.ncbi.nlm.nih.gov/pmc/articles/PMC3375761/ | E33: 45352 | F33: Other | G33: National Burden study | H33: 2006 | I33: 2006 | J33: United States of America | K33: =IF(J33<>"", VLOOKUP(J33, 'Drop down values'!$C$2:$D$195, 2, FALSE), "") -> USA | S33: Cyclospora cayetanensis | U33: 0 | AB33: 0 | AG33: 0
A34: Thomas | B34: 2015 | C34: Estimates of Foodborne Illness–Related Hospitalizations and Deaths in Canada for 30 Specified Pathogens and Unspecified Agents | D34: https://pubmed.ncbi.nlm.nih.gov/26259128/ | E34: 45996 | F34: Other | G34: National Burden study | H34: 2000 | I34: 2010 | J34: Canada | S34: Cyclospora cayetanensis | U34: 0 | AB34: 0 | AG34: 0
A35: Scallan | B35: 2011 | C35: Foodborne illness acquired in the United States--major pathogens United States—Major Pathogens | D35: https://www.ncbi.nlm.nih.gov/pmc/articles/PMC3375761/ | E35: 45352 | F35: Other | G35: National Burden study | H35: 2006 | I35: 2006 | J35: United States of America | K35: =IF(J35<>"", VLOOKUP(J35, 'Drop down values'!$C$2:$D$195, 2, FALSE), "") -> USA | S35: Diarrheagenic E. coli other than STEC and ETEC | U35: 0 | AB35: 0 | AG35: 0
A36: Glass | B36: 2023 | C36: The Cost of Foodborne Illness and Its Sequelae in Australia Circa 2019 | D36: https://pubmed.ncbi.nlm.nih.gov/37610847/ | E36: 45425 | F36: Other | G36: National Burden study | H36: 2019 | I36: 2019 | J36: Australia | K36: =IF(J36<>"", VLOOKUP(J36, 'Drop down values'!$C$2:$D$195, 2, FALSE), "") -> AUS | S36: E coli | U36: 1 | AB36: 0 | AG36: 1
A37: Holland | B37: 2020 | C37: Estimating deaths from foodborne disease in the UK for 11 key pathogens | D37: https://bmjopengastro.bmj.com/content/7/1/e000377 | E37: 45419 | F37: Other | G37: National Burden study | H37: 2018 | I37: 2018 | J37: United Kingdom | K37: =IF(J37<>"", VLOOKUP(J37, 'Drop down values'!$C$2:$D$195, 2, FALSE), "") -> GBR | S37: E coli | U37: 2
A38: Mead | B38: 1999 | C38: Food-related illness and death in the United States. | D38: https://www.ncbi.nlm.nih.gov/pmc/articles/PMC2627714/ | E38: 45390 | F38: Other | G38: National Burden study | H38: 1997 | I38: 1997 | J38: United States of America | K38: =IF(J38<>"", VLOOKUP(J38, 'Drop down values'!$C$2:$D$195, 2, FALSE), "") -> USA | S38: E coli | U38: 61
A39: Mead | B39: 1999 | C39: Food-related illness and death in the United States. | D39: https://www.ncbi.nlm.nih.gov/pmc/articles/PMC2627714/ | E39: 45390 | F39: Other | G39: National Burden study | H39: 1997 | I39: 1997 | J39: United States of America | K39: =IF(J39<>"", VLOOKUP(J39, 'Drop down values'!$C$2:$D$195, 2, FALSE), "") -> USA | S39: E coli | U39: 30
A40: Mead | B40: 1999 | C40: Food-related illness and death in the United States. | D40: https://www.ncbi.nlm.nih.gov/pmc/articles/PMC2627714/ | E40: 45390 | F40: Other | G40: National Burden study | H40: 1997 | I40: 1997 | J40: United States of America | K40: =IF(J40<>"", VLOOKUP(J40, 'Drop down values'!$C$2:$D$195, 2, FALSE), "") -> USA | S40: E coli, other diarrheogenic | U40: 0
...

Sheet Drop down values
A1: OPT_STUDY_TYPE | B1: REF_LOC_LEVEL | C1: REF_LOCATION | D1: REF_LOCATION_ISO3 | E1: REF_SEX | F1: OPT_CASES | G1: VALUE_UNIT
A2: Outbreak report | B2: National | C2: Afghanistan | D2: AFG | E2: All sexes | F2: All | G2: Days
A3: Cross-sectional study | B3: Sub-national | C3: Albania | D3: ALB | E3: Male | F3: Confirmed | G3: Weeks
A4: Active surveillance | B4: Regional | C4: Algeria | D4: DZA | E4: Female | F4: Probable | G4: Months
A5: Passive surveillance | B5: Global | C5: Andorra | D5: AND | F5: Suspected | G5: Years
A6: Cohort study | C6: Angola | D6: AGO | F6: Other | G6: Other
A7: Case series | C7: Antigua and Barbuda | D7: ATG
A8: Modelling study | C8: Argentina | D8: ARG
A9: Other | C9: Armenia | D9: ARM
C10: Australia | D10: AUS
C11: Austria | D11: AUT
C12: Azerbaijan | D12: AZE
C13: Bahamas | D13: BHS
C14: Bahrain | D14: BHR
C15: Bangladesh | D15: BGD
C16: Barbados | D16: BRB
C17: Belarus | D17: BLR
C18: Belgium | D18: BEL
C19: Belize | D19: BLZ
C20: Benin | D20: BEN
C21: Bhutan | D21: BTN
... C195: Zimbabwe | D195: ZWE
